#VRML_SIM R2025a utf8

EXTERNPROTO "https://raw.githubusercontent.com/cyberbotics/webots/R2025a/projects/objects/backgrounds/protos/TexturedBackground.proto"
EXTERNPROTO "https://raw.githubusercontent.com/cyberbotics/webots/R2025a/projects/objects/backgrounds/protos/TexturedBackgroundLight.proto"
EXTERNPROTO "https://raw.githubusercontent.com/cyberbotics/webots/R2025a/projects/objects/floors/protos/RectangleArena.proto"
EXTERNPROTO "https://raw.githubusercontent.com/cyberbotics/webots/R2025a/projects/appearances/protos/PorcelainChevronTiles.proto"
EXTERNPROTO "https://raw.githubusercontent.com/cyberbotics/webots/R2025a/projects/appearances/protos/Parquetry.proto"
EXTERNPROTO "https://raw.githubusercontent.com/cyberbotics/webots/R2025a/projects/appearances/protos/Cardboard.proto"
EXTERNPROTO "https://raw.githubusercontent.com/cyberbotics/webots/R2025a/projects/appearances/protos/BlanketFabric.proto"
EXTERNPROTO "https://raw.githubusercontent.com/cyberbotics/webots/R2025a/projects/appearances/protos/Leather.proto"
EXTERNPROTO "https://raw.githubusercontent.com/cyberbotics/webots/R2025a/projects/appearances/protos/Rubber.proto"
EXTERNPROTO "https://raw.githubusercontent.com/cyberbotics/webots/R2025a/projects/appearances/protos/DamascusSteel.proto"
EXTERNPROTO "https://raw.githubusercontent.com/cyberbotics/webots/R2025a/projects/appearances/protos/Pcb.proto"

WorldInfo {
}
Viewpoint {
  orientation -0.20764365688290934 -0.5833900778132785 0.7852006933678227 5.432021023093273
  position -5.850668714567814 4.290953989807577 4.371721796752011
}
TexturedBackground {
}
TexturedBackgroundLight {
}
RectangleArena {
  translation 1.59215e-07 0 0.03
  rotation 0 1 0 5.30716e-06
  floorSize 4 4
  floorAppearance Parquetry {
  }
  wallAppearance PorcelainChevronTiles {
  }
}
DEF Obs1 Solid {
  translation 1.69614 -0.072898 0.142502
  rotation -0.0025754902978973823 0.002671230308971273 0.9999931156654838 -1.5881053071795863
  children [
    Shape {
      appearance PBRAppearance {
      }
      geometry Box {
        size 1 0.05 0.5
      }
    }
  ]
}
Robot {
  translation 0.8388530436465288 0.6277896964911703 0.06963760944111344
  rotation 0.00432485989149664 -0.005676070648248133 -0.9999745385803156 -0.2434897398267717
  children [
    DEF gps GPS {
      translation -0.05 -0.02 0.03
      children [
        Shape {
          appearance PBRAppearance {
          }
          geometry Cylinder {
            height 0.02
            radius 0.02
          }
        }
      ]
      boundingObject Shape {
        appearance PBRAppearance {
        }
        geometry Cylinder {
          height 0.02
          radius 0.02
        }
      }
      physics Physics {
      }
    }
    DEF lidar Lidar {
      translation 0.07 -0.02 0.04
      children [
        Shape {
          appearance PBRAppearance {
          }
          geometry Cylinder {
            height 0.025
            radius 0.025
          }
        }
      ]
      boundingObject Shape {
        appearance PBRAppearance {
        }
        geometry Cylinder {
          height 0.025
          radius 0.025
        }
      }
      physics Physics {
      }
      horizontalResolution 128
      fieldOfView 3.14
      verticalFieldOfView 0.1
      numberOfLayers 1
    }
    DEF BODY Shape {
      appearance PBRAppearance {
        baseColor 0.917647 0.145098 0.145098
        roughness 1
        metalness 0
      }
      geometry Box {
        size 0.2 0.1 0.05
      }
    }
    DEF WHEEL1 HingeJoint {
      jointParameters HingeJointParameters {
        position 22735.876122635076
        axis 0 1 0
        anchor 0.05 0.06 0
      }
      device [
        RotationalMotor {
          name "wheel1"
        }
      ]
      endPoint Solid {
        translation 0.05087192895508301 0.06043224674532349 0.00025316895804459495
        rotation -0.063412533572684 0.6989009602724934 -0.712401781522253 3.2552867128939935
        children [
          DEF WHEEL Shape {
            appearance PBRAppearance {
              baseColor 0.305882 0.898039 0.25098
              roughness 1
              metalness 0
            }
            geometry Cylinder {
              height 0.02
              radius 0.04
              subdivision 24
            }
          }
        ]
        boundingObject USE WHEEL
        physics Physics {
        }
        linearVelocity 0.03892193898198375 0.009524135473194913 -0.00019417252081411858
        angularVelocity -0.23652120468004537 0.9669990092626749 -0.0008688645315372393
      }
    }
    DEF WHEEL2 HingeJoint {
      jointParameters HingeJointParameters {
        position 18369.320834332444
        axis 0 1 0
        anchor 0.05 -0.06 0
      }
      device [
        RotationalMotor {
          name "wheel2"
        }
      ]
      endPoint Solid {
        translation 0.05000048622550095 -0.06000008469764562 -2.16676284516266e-06
        rotation -0.1521016639505213 0.6988781913508296 -0.6988807891748604 3.443481035042517
        children [
          USE WHEEL
        ]
        name "solid(1)"
        boundingObject USE WHEEL
        physics Physics {
        }
        linearVelocity 0.03867600452784261 0.009461284107001712 0.0002315066878375222
        angularVelocity -0.23652082746612188 0.9669973242386753 -0.0008687553033174295
      }
    }
    DEF WHEEL3 HingeJoint {
      jointParameters HingeJointParameters {
        position 22735.888206402342
        axis 0 1 0
        anchor -0.05 0.06 0
      }
      device [
        RotationalMotor {
          name "wheel3"
        }
      ]
      endPoint Solid {
        translation -0.04999605640271287 0.060000084994313085 -2.4509978427520987e-06
        rotation 0.06445219276562951 -0.7056352562805485 0.7056378674232178 3.012866732892994
        children [
          USE WHEEL
        ]
        name "solid(2)"
        boundingObject USE WHEEL
        physics Physics {
        }
        linearVelocity 0.03867094947792838 0.009453627424773793 0.00020753953522329122
        angularVelocity -0.23652061645962266 0.966996821807587 -0.0008686930478111151
      }
    }
    DEF WHEEL4 HingeJoint {
      jointParameters HingeJointParameters {
        position 18369.326726428695
        axis 0 1 0
        anchor -0.05 -0.06 0
      }
      device [
        RotationalMotor {
          name "wheel4"
        }
      ]
      endPoint Solid {
        translation -0.04999928512752186 -0.05999991499841628 -1.9773168972075636e-06
        rotation -0.15420855056391927 0.6986472963468724 -0.6986498967581549 3.4475982105857046
        children [
          USE WHEEL
        ]
        name "solid(3)"
        boundingObject USE WHEEL
        physics Physics {
        }
        linearVelocity 0.0386772078360922 0.009454764241148461 -0.00021016966922060811
        angularVelocity -0.23652073828291684 0.9669973134517797 -0.0008686883394907645
      }
    }
    DEF DS_RIGHT DistanceSensor {
      translation 0.1 -0.03 0
      rotation 0 0 1 -0.3
      children [
        Shape {
          appearance PBRAppearance {
            baseColor 0.184314 0.596078 0.847059
            roughness 1
            metalness 0
          }
          geometry Box {
            size 0.01 0.01 0.01
          }
        }
      ]
      name "ds_right"
    }
    DEF DS_LEFT DistanceSensor {
      translation 0.1 0.03 0
      rotation 0 0 1 0.3
      children [
        Shape {
          appearance PBRAppearance {
            baseColor 0.184314 0.596078 0.847059
            roughness 1
            metalness 0
          }
          geometry Box {
            size 0.01 0.01 0.01
          }
        }
      ]
      name "ds_left"
    }
  ]
  boundingObject USE BODY
  physics Physics {
    density -1
    mass 1
  }
  controller "controlador"
  window "<none>"
  linearVelocity 0.03866480839921348 0.009446924023268664 0.00023037765570072476
  angularVelocity 0.004557473847407216 -0.003507578877339175 7.908590510681165e-05
}
Solid {
  translation 0 -1.21 0.34
  children [
    Shape {
      appearance Rubber {
      }
      geometry Box {
        size 0.6 0.6 0.6
      }
    }
  ]
  name "solid(1)"
}
Solid {
  translation 0 1.15 0.43
  children [
    Shape {
      appearance BlanketFabric {
      }
      geometry Cone {
        bottomRadius 0.5
        height 0.8
      }
    }
  ]
  name "solid(2)"
}
Solid {
  translation -1.2 0 0.53
  children [
    Shape {
      appearance Cardboard {
      }
      geometry Cylinder {
        height 1
        radius 0.05
      }
    }
  ]
  name "solid(3)"
}
Solid {
  translation -1.49 -0.78 0.45
  children [
    Shape {
      appearance Pcb {
      }
      geometry Cylinder {
        height 0.8
        radius 0.2
      }
    }
  ]
  name "solid(4)"
}
Solid {
  translation 0 0 0.18
  children [
    Shape {
      appearance DamascusSteel {
      }
      geometry Capsule {
        height 0.1
        radius 0.05
      }
    }
  ]
  name "solid(5)"
}
Solid {
  translation -1.24 0.86 0.32
  children [
    Shape {
      appearance Leather {
      }
      geometry Sphere {
        radius 0.3
      }
    }
  ]
  name "solid(6)"
}
