#VRML_SIM R2025a utf8

EXTERNPROTO "https://raw.githubusercontent.com/cyberbotics/webots/R2025a/projects/objects/backgrounds/protos/TexturedBackground.proto"
EXTERNPROTO "https://raw.githubusercontent.com/cyberbotics/webots/R2025a/projects/objects/backgrounds/protos/TexturedBackgroundLight.proto"
EXTERNPROTO "https://raw.githubusercontent.com/cyberbotics/webots/R2025a/projects/objects/floors/protos/RectangleArena.proto"
EXTERNPROTO "https://raw.githubusercontent.com/cyberbotics/webots/R2025a/projects/appearances/protos/PorcelainChevronTiles.proto"
EXTERNPROTO "https://raw.githubusercontent.com/cyberbotics/webots/R2025a/projects/appearances/protos/Parquetry.proto"
EXTERNPROTO "https://raw.githubusercontent.com/cyberbotics/webots/R2025a/projects/appearances/protos/Cardboard.proto"
EXTERNPROTO "https://raw.githubusercontent.com/cyberbotics/webots/R2025a/projects/appearances/protos/BlanketFabric.proto"
EXTERNPROTO "https://raw.githubusercontent.com/cyberbotics/webots/R2025a/projects/appearances/protos/Leather.proto"
EXTERNPROTO "https://raw.githubusercontent.com/cyberbotics/webots/R2025a/projects/appearances/protos/Rubber.proto"
EXTERNPROTO "https://raw.githubusercontent.com/cyberbotics/webots/R2025a/projects/appearances/protos/DamascusSteel.proto"
EXTERNPROTO "https://raw.githubusercontent.com/cyberbotics/webots/R2025a/projects/appearances/protos/Pcb.proto"

WorldInfo {
}
Viewpoint {
  orientation -0.18342089226463662 -0.5092790401622195 0.8408279464505762 5.473812860576964
  position -5.461981433816083 3.9741378853477722 4.086573171778761
}
TexturedBackground {
}
TexturedBackgroundLight {
}
RectangleArena {
  translation 1.59215e-07 0 0.03
  rotation 0 1 0 5.30716e-06
  floorSize 4 4
  floorAppearance Parquetry {
  }
  wallAppearance PorcelainChevronTiles {
  }
}
DEF Obs1 Solid {
  translation 1.69614 -0.072898 0.142502
  rotation -0.0025754902978973823 0.002671230308971273 0.9999931156654838 -1.5881053071795863
  children [
    Shape {
      appearance PBRAppearance {
      }
      geometry Box {
        size 1 0.05 0.5
      }
    }
  ]
}
Robot {
  translation 1.358070349185821 0.6710075375554935 0.0698924147112729
  rotation -0.00418922808863864 0.0010539008255943357 -0.9999906697870092 -1.2117484441497384
  children [
    DEF gps GPS {
      translation -0.05 -0.02 0.03
      children [
        Shape {
          appearance PBRAppearance {
          }
          geometry Cylinder {
            height 0.02
            radius 0.02
          }
        }
      ]
      boundingObject Shape {
        appearance PBRAppearance {
        }
        geometry Cylinder {
          height 0.02
          radius 0.02
        }
      }
      physics Physics {
      }
    }
    DEF lidar Lidar {
      translation 0.07 -0.02 0.04
      children [
        Shape {
          appearance PBRAppearance {
          }
          geometry Cylinder {
            height 0.025
            radius 0.025
          }
        }
      ]
      boundingObject Shape {
        appearance PBRAppearance {
        }
        geometry Cylinder {
          height 0.025
          radius 0.025
        }
      }
      physics Physics {
      }
      horizontalResolution 128
      fieldOfView 3.14
      verticalFieldOfView 0.1
      numberOfLayers 1
    }
    DEF BODY Shape {
      appearance PBRAppearance {
        baseColor 0.917647 0.145098 0.145098
        roughness 1
        metalness 0
      }
      geometry Box {
        size 0.2 0.1 0.05
      }
    }
    DEF WHEEL1 HingeJoint {
      jointParameters HingeJointParameters {
        position 21436.566421050946
        axis 0 1 0
        anchor 0.05 0.06 0
      }
      device [
        RotationalMotor {
          name "wheel1"
        }
      ]
      endPoint Solid {
        translation 0.05046970148530363 0.06043224674532349 -0.0007770039502686594
        rotation 0.5476471717754787 -0.5878147405853517 0.5954463922108312 2.162958023155971
        children [
          DEF WHEEL Shape {
            appearance PBRAppearance {
              baseColor 0.305882 0.898039 0.25098
              roughness 1
              metalness 0
            }
            geometry Cylinder {
              height 0.02
              radius 0.04
              subdivision 24
            }
          }
        ]
        boundingObject USE WHEEL
        physics Physics {
        }
        linearVelocity 0.014102743610966133 0.03685036897296324 -0.00013493539493139147
        angularVelocity -0.9333669277511245 0.3522286027926183 0.0009460282701968855
      }
    }
    DEF WHEEL2 HingeJoint {
      jointParameters HingeJointParameters {
        position 17524.110369473434
        axis 0 1 0
        anchor 0.05 -0.06 0
      }
      device [
        RotationalMotor {
          name "wheel2"
        }
      ]
      endPoint Solid {
        translation 0.04999925361285943 -0.06000008469764562 2.091454685460308e-06
        rotation 0.9769560403125527 0.15092503498375381 -0.1509255747445428 1.59411155246185
        children [
          USE WHEEL
        ]
        name "solid(1)"
        boundingObject USE WHEEL
        physics Physics {
        }
        linearVelocity 0.014286180092045426 0.03731408810679539 0.0001255168037286625
        angularVelocity -0.9333690187488015 0.3522290796737036 0.0009458984613822107
      }
    }
    DEF WHEEL3 HingeJoint {
      jointParameters HingeJointParameters {
        position 21436.57748788131
        axis 0 1 0
        anchor -0.05 0.06 0
      }
      device [
        RotationalMotor {
          name "wheel3"
        }
      ]
      endPoint Solid {
        translation -0.05000134521814649 0.060000084994313085 -4.444067745503582e-06
        rotation -0.5465755267854338 0.5921370508350573 -0.5921392627985299 4.142010091866184
        children [
          USE WHEEL
        ]
        name "solid(2)"
        boundingObject USE WHEEL
        physics Physics {
        }
        linearVelocity 0.014166755543080127 0.0376431910635909 0.00010820494968829797
        angularVelocity -0.9333696090093073 0.35222935388973997 0.0009458587697452426
      }
    }
    DEF WHEEL4 HingeJoint {
      jointParameters HingeJointParameters {
        position 17524.11565439007
        axis 0 1 0
        anchor -0.05 -0.06 0
      }
      device [
        RotationalMotor {
          name "wheel4"
        }
      ]
      endPoint Solid {
        translation -0.05000095140930274 -0.05999991499841628 1.8750053628346235e-06
        rotation 0.9761703805175906 0.15344578571779324 -0.1534463393033256 1.5949158464186617
        children [
          USE WHEEL
        ]
        name "solid(3)"
        boundingObject USE WHEEL
        physics Physics {
        }
        linearVelocity 0.014072146424345722 0.03738791780011614 -0.00010739095340274179
        angularVelocity -0.933370838975555 0.3522296706798334 0.000945508658974638
      }
    }
    DEF DS_RIGHT DistanceSensor {
      translation 0.1 -0.03 0
      rotation 0 0 1 -0.3
      children [
        Shape {
          appearance PBRAppearance {
            baseColor 0.184314 0.596078 0.847059
            roughness 1
            metalness 0
          }
          geometry Box {
            size 0.01 0.01 0.01
          }
        }
      ]
      name "ds_right"
    }
    DEF DS_LEFT DistanceSensor {
      translation 0.1 0.03 0
      rotation 0 0 1 0.3
      children [
        Shape {
          appearance PBRAppearance {
            baseColor 0.184314 0.596078 0.847059
            roughness 1
            metalness 0
          }
          geometry Box {
            size 0.01 0.01 0.01
          }
        }
      ]
      name "ds_left"
    }
  ]
  boundingObject USE BODY
  physics Physics {
    density -1
    mass 1
  }
  controller "controlador"
  window "<none>"
  linearVelocity 0.01423016424580694 0.03746642424826108 0.0001204399952360596
  angularVelocity 0.002869210264400717 0.0008782353131099697 -0.0022653141559174183
}
Solid {
  translation 0 -1.21 0.34
  children [
    Shape {
      appearance Rubber {
      }
      geometry Box {
        size 0.6 0.6 0.6
      }
    }
  ]
  name "solid(1)"
}
Solid {
  translation 0 1.15 0.43
  children [
    Shape {
      appearance BlanketFabric {
      }
      geometry Cone {
        bottomRadius 0.5
        height 0.8
      }
    }
  ]
  name "solid(2)"
}
Solid {
  translation -1.2 0 0.53
  children [
    Shape {
      appearance Cardboard {
      }
      geometry Cylinder {
        height 1
        radius 0.05
      }
    }
  ]
  name "solid(3)"
}
Solid {
  translation -1.49 -0.78 0.45
  children [
    Shape {
      appearance Pcb {
      }
      geometry Cylinder {
        height 0.8
        radius 0.2
      }
    }
  ]
  name "solid(4)"
}
Solid {
  translation 0 0 0.18
  children [
    Shape {
      appearance DamascusSteel {
      }
      geometry Capsule {
        height 0.1
        radius 0.05
      }
    }
  ]
  name "solid(5)"
}
Solid {
  translation -1.24 0.86 0.32
  children [
    Shape {
      appearance Leather {
      }
      geometry Sphere {
        radius 0.3
      }
    }
  ]
  name "solid(6)"
}
