#VRML_SIM R2025a utf8

EXTERNPROTO "https://raw.githubusercontent.com/cyberbotics/webots/R2025a/projects/objects/backgrounds/protos/TexturedBackground.proto"
EXTERNPROTO "https://raw.githubusercontent.com/cyberbotics/webots/R2025a/projects/objects/backgrounds/protos/TexturedBackgroundLight.proto"
EXTERNPROTO "https://raw.githubusercontent.com/cyberbotics/webots/R2025a/projects/objects/floors/protos/RectangleArena.proto"

WorldInfo {
}
Viewpoint {
  orientation -0.0070890680056492844 0.9998359030357282 0.016670696312429754 0.8046674665906733
  position -5.020801848925522 0.09739257364557652 5.012574453144166
}
TexturedBackground {
}
TexturedBackgroundLight {
}
RectangleArena {
  translation 1.59215e-07 0 0.03
  rotation 0 1 0 5.30716e-06
  floorSize 4 4
}
DEF Obs1 Solid {
  translation 1.69614 -0.072898 0.142502
  rotation -0.0025754902978973823 0.002671230308971273 0.9999931156654838 -1.5881053071795863
  children [
    Shape {
      appearance PBRAppearance {
      }
      geometry Box {
        size 1 0.05 0.5
      }
    }
  ]
}
Robot {
  translation 1.7135232046252544 0.9451504394558827 0.0696506079676303
  rotation -0.00028194668253086395 -0.0008240013818520711 0.9999996207638235 -1.5827096592413588
  children [
    DEF gps GPS {
      translation -0.05 -0.02 0.03
      children [
        Shape {
          appearance PBRAppearance {
          }
          geometry Cylinder {
            height 0.02
            radius 0.02
          }
        }
      ]
      boundingObject Shape {
        appearance PBRAppearance {
        }
        geometry Cylinder {
          height 0.02
          radius 0.02
        }
      }
      physics Physics {
      }
    }
    DEF lidar Lidar {
      translation 0.07 -0.02 0.04
      children [
        Shape {
          appearance PBRAppearance {
          }
          geometry Cylinder {
            height 0.025
            radius 0.025
          }
        }
      ]
      boundingObject Shape {
        appearance PBRAppearance {
        }
        geometry Cylinder {
          height 0.025
          radius 0.025
        }
      }
      physics Physics {
      }
      horizontalResolution 128
      fieldOfView 3.14
      verticalFieldOfView 0.1
      numberOfLayers 1
    }
    DEF BODY Shape {
      appearance PBRAppearance {
        baseColor 0.917647 0.145098 0.145098
        roughness 1
        metalness 0
      }
      geometry Box {
        size 0.2 0.1 0.05
      }
    }
    DEF WHEEL1 HingeJoint {
      jointParameters HingeJointParameters {
        position 18790.119057458334
        axis 0 1 0
        anchor 0.05 0.06 0
      }
      device [
        RotationalMotor {
          name "wheel1"
        }
      ]
      endPoint Solid {
        translation 0.050889971577776326 0.06043224674532349 0.00017973651487624236
        rotation -0.09321691024548152 0.6973738698833996 -0.7106196544200963 3.3134513345396925
        children [
          DEF WHEEL Shape {
            appearance PBRAppearance {
              baseColor 0.305882 0.898039 0.25098
              roughness 1
              metalness 0
            }
            geometry Cylinder {
              height 0.02
              radius 0.04
              subdivision 24
            }
          }
        ]
        boundingObject USE WHEEL
        physics Physics {
        }
      }
    }
    DEF WHEEL2 HingeJoint {
      jointParameters HingeJointParameters {
        position 15236.40821895057
        axis 0 1 0
        anchor 0.05 -0.06 0
      }
      device [
        RotationalMotor {
          name "wheel2"
        }
      ]
      endPoint Solid {
        translation 0.049998173906171124 -0.06000008469764562 1.2635892501430175e-06
        rotation 0.9755192330375927 -0.15550247593341082 0.15550307377131198 1.5955829005917557
        children [
          USE WHEEL
        ]
        name "solid(1)"
        boundingObject USE WHEEL
        physics Physics {
        }
      }
    }
    DEF WHEEL3 HingeJoint {
      jointParameters HingeJointParameters {
        position 18790.12797019694
        axis 0 1 0
        anchor -0.05 0.06 0
      }
      device [
        RotationalMotor {
          name "wheel3"
        }
      ]
      endPoint Solid {
        translation -0.049996265263342964 0.060000084994313085 -2.7588207790320863e-06
        rotation 0.09287272354524516 -0.70404935446018 0.7040519609414437 2.9563791207840078
        children [
          USE WHEEL
        ]
        name "solid(2)"
        boundingObject USE WHEEL
        physics Physics {
        }
      }
    }
    DEF WHEEL4 HingeJoint {
      jointParameters HingeJointParameters {
        position 15236.41232663614
        axis 0 1 0
        anchor -0.05 -0.06 0
      }
      device [
        RotationalMotor {
          name "wheel4"
        }
      ]
      endPoint Solid {
        translation -0.050001867533727075 -0.05999991499841628 9.659930383989687e-07
        rotation 0.9761388145580882 -0.1535461399370719 0.15354672781780637 1.5949481685870905
        children [
          USE WHEEL
        ]
        name "solid(3)"
        boundingObject USE WHEEL
        physics Physics {
        }
      }
    }
    DEF DS_RIGHT DistanceSensor {
      translation 0.1 -0.03 0
      rotation 0 0 1 -0.3
      children [
        Shape {
          appearance PBRAppearance {
            baseColor 0.184314 0.596078 0.847059
            roughness 1
            metalness 0
          }
          geometry Box {
            size 0.01 0.01 0.01
          }
        }
      ]
      name "ds_right"
    }
    DEF DS_LEFT DistanceSensor {
      translation 0.1 0.03 0
      rotation 0 0 1 0.3
      children [
        Shape {
          appearance PBRAppearance {
            baseColor 0.184314 0.596078 0.847059
            roughness 1
            metalness 0
          }
          geometry Box {
            size 0.01 0.01 0.01
          }
        }
      ]
      name "ds_left"
    }
  ]
  boundingObject USE BODY
  physics Physics {
    density -1
    mass 1
  }
  controller "controlador"
  window "<none>"
  linearVelocity -0.00062663025274943 -0.039799783925840895 0.00022916043971865952
  angularVelocity -0.00454887411737234 -0.0035470722603544694 3.3536698107153254e-05
}
Solid {
  translation 0 -0.96 0
  children [
    Shape {
      appearance PBRAppearance {
      }
      geometry Box {
        size 0.9 0.05 0.6
      }
    }
  ]
  name "solid(1)"
}
Solid {
  translation 0 1.15 0.09
  children [
    Shape {
      appearance PBRAppearance {
      }
      geometry Box {
        size 2 0.05 0.6
      }
    }
  ]
  name "solid(2)"
}
