#VRML_SIM R2025a utf8

EXTERNPROTO "https://raw.githubusercontent.com/cyberbotics/webots/R2025a/projects/objects/backgrounds/protos/TexturedBackground.proto"
EXTERNPROTO "https://raw.githubusercontent.com/cyberbotics/webots/R2025a/projects/objects/backgrounds/protos/TexturedBackgroundLight.proto"
EXTERNPROTO "https://raw.githubusercontent.com/cyberbotics/webots/R2025a/projects/objects/floors/protos/RectangleArena.proto"
EXTERNPROTO "https://raw.githubusercontent.com/cyberbotics/webots/R2025a/projects/appearances/protos/RoughPolymer.proto"

WorldInfo {
}
Viewpoint {
  orientation 0.24589808549564587 -0.024842168717797205 -0.9689772949883668 3.3367436754344357
  position 0.29041450815739567 -1.089332683598203 -1.5578048576385777
}
TexturedBackground {
}
TexturedBackgroundLight {
}
Robot {
  translation -0.8342295447691946 -0.8597671569033393 -2.1804789505796496
  rotation -2.153032723688224e-09 1.1065639819123965e-08 0.9999999999999999 -2.7579572371445082
  children [
    Lidar {
      children [
        Shape {
          appearance RoughPolymer {
          }
          geometry Cylinder {
            height 0.075
            radius 0.025
          }
        }
      ]
      boundingObject Shape {
        appearance Appearance {
          texture ImageTexture {
          }
        }
        geometry Box {
          size 0.1 0.1 0.1
        }
      }
      physics Physics {
      }
    }
    DEF BODY Shape {
      appearance PBRAppearance {
        baseColor 0.917647 0.145098 0.145098
        roughness 1
        metalness 0
      }
      geometry Box {
        size 0.2 0.1 0.05
      }
    }
    DEF WHEEL1 HingeJoint {
      jointParameters HingeJointParameters {
        position 98.80310961809514
        axis 0 1 0
        anchor 0.05 0.06 0
      }
      device [
        RotationalMotor {
          name "wheel1"
        }
      ]
      endPoint Solid {
        translation 0.04999999999999871 0.06000000000017536 7.840251635027329e-06
        rotation -0.5169734827463928 0.6052832917898615 -0.6052855151224872 -2.187327635567443
        children [
          DEF WHEEL Shape {
            appearance PBRAppearance {
              baseColor 0.305882 0.898039 0.25098
              roughness 1
              metalness 0
            }
            geometry Cylinder {
              height 0.02
              radius 0.04
              subdivision 24
            }
          }
        ]
        boundingObject USE WHEEL
        physics Physics {
        }
      }
    }
    DEF WHEEL2 HingeJoint {
      jointParameters HingeJointParameters {
        position 86.00424329684124
        axis 0 1 0
        anchor 0.05 -0.06 0
      }
      device [
        RotationalMotor {
          name "wheel2"
        }
      ]
      endPoint Solid {
        translation 0.05000000000000138 -0.05999999999983102 7.84030365563737e-06
        rotation -0.42838156339323236 0.6389390569585484 -0.6389414039156415 -2.3321325688449277
        children [
          USE WHEEL
        ]
        name "solid(1)"
        boundingObject USE WHEEL
        physics Physics {
        }
      }
    }
    DEF WHEEL3 HingeJoint {
      jointParameters HingeJointParameters {
        position 98.80311356304249
        axis 0 1 0
        anchor -0.05 0.06 0
      }
      device [
        RotationalMotor {
          name "wheel3"
        }
      ]
      endPoint Solid {
        translation -0.050000000000001155 0.06000000000017813 7.840251651902719e-06
        rotation -0.5169749957400932 0.6052826456657064 -0.6052848689959578 -2.187325247758052
        children [
          USE WHEEL
        ]
        name "solid(2)"
        boundingObject USE WHEEL
        physics Physics {
        }
      }
    }
    DEF WHEEL4 HingeJoint {
      jointParameters HingeJointParameters {
        position 86.0042472528746
        axis 0 1 0
        anchor -0.05 -0.06 0
      }
      device [
        RotationalMotor {
          name "wheel4"
        }
      ]
      endPoint Solid {
        translation -0.04999999999999849 -0.05999999999982841 7.840303672068671e-06
        rotation -0.4283830591574701 0.6389385555368287 -0.6389409024905186 -2.3321300411812405
        children [
          USE WHEEL
        ]
        name "solid(3)"
        boundingObject USE WHEEL
        physics Physics {
        }
      }
    }
    DEF DS_RIGHT DistanceSensor {
      translation 0.1 -0.03 0
      rotation 0 0 1 -0.3
      children [
        Shape {
          appearance PBRAppearance {
            baseColor 0.184314 0.596078 0.847059
            roughness 1
            metalness 0
          }
          geometry Box {
            size 0.01 0.01 0.01
          }
        }
      ]
      name "ds_right"
    }
    DEF DS_LEFT DistanceSensor {
      translation 0.1 0.03 0
      rotation 0 0 1 0.3
      children [
        Shape {
          appearance PBRAppearance {
            baseColor 0.184314 0.596078 0.847059
            roughness 1
            metalness 0
          }
          geometry Box {
            size 0.01 0.01 0.01
          }
        }
      ]
      name "ds_left"
    }
  ]
  boundingObject USE BODY
  physics Physics {
    density -1
    mass 1
  }
  controller "mi_controlador"
}
RectangleArena {
  translation 0 0 -2.22
  rotation 0 0 1 4.692820414042842e-06
  floorSize 3 3
}
